<robot name="meloha">

    <link name="base_link"/>

    <joint name="base_joint" type="fixed">
        <parent link="base_link"/>
        <child link="head"/>
        <origin xyz="0 0 1.0" rpy="1.57 0 1.57"/>  
    </joint>

    <link name="head">
        <visual>
            <geometry>
                <box size="0.1 0.1 0.1"/>
            </geometry>
            <origin xyz="0 0 0" rpy="0 0 0"/>
            <material name="gray">
                <color rgba="0.6 0.6 0.6 1.0"/>
            </material>  
        </visual>
    </link>

    <!-- left arm -->
    <joint name="joint_1_left" type="revolute">
        <parent link="head"/>
        <child link="motor_1_left"/>
        <origin xyz="-0.1 0 0 " rpy="1.57 0 -1.57"/> <!-- -0.1 매크로로 변경-->
        <axis xyz="0 0 1"/>
        <limit effort="1.0" lower="-3.14" upper="3.14" velocity="1.0"/>
    </joint>

    <link name="motor_1_left">
        <visual>
            <geometry>
                <box size="0.054 0.054 0.126"/>
            </geometry>
            <origin xyz="0 0 -0.063" rpy="0 0 0"/>
            <material name="gray">
                <color rgba="0.6 0.6 0.6 1.0"/>
            </material>  
        </visual>
    </link>

    <joint name="joint_2_left" type="revolute">
        <parent link="motor_1_left"/>
        <child link="motor_2_left"/>
        <origin xyz="0 0 0.23 " rpy="-1.57 0 0"/> <!-- 0.2 매크로로 변경-->
        <axis xyz="0 0 1"/>
        <limit effort="1.0" lower="-3.14" upper="3.14" velocity="1.0"/>
    </joint>

    <link name="motor_2_left">
        <visual>
            <geometry>
                <box size="0.054 0.054 0.126"/>
            </geometry>
            <origin xyz="0 0 0" rpy="0 0 0"/>
            <material name="gray">
                <color rgba="0.6 0.6 0.6 1.0"/>
            </material>  
        </visual>
    </link>

    <joint name="joint_3_left" type="revolute">
        <parent link="motor_2_left"/>
        <child link="motor_3_left"/>
        <origin xyz="0.3 0 0 " rpy="0 0 0"/> <!-- 0.3 매크로로 변경-->
        <axis xyz="0 0 1"/>
        <limit effort="1.0" lower="-3.14" upper="3.14" velocity="1.0"/>
    </joint>

    <link name="motor_3_left">
        <visual>
            <geometry>
                <box size="0.054 0.054 0.126"/>
            </geometry>
            <origin xyz="0 0 0" rpy="0 0 0"/>
            <material name="gray">
                <color rgba="0.6 0.6 0.6 1.0"/>
            </material>  
        </visual>
    </link>

    <joint name="ee_left_connect" type="fixed">
        <parent link="motor_3_left"/>
        <child link="ee_left"/>
        <origin xyz="0.5 0 0 " rpy="0 0 0"/> <!-- 0.3 매크로로 변경-->
    </joint>

    <link name="ee_left">
        <visual>
            <geometry>
                <sphere radius="0.04"/>
            </geometry>
            <origin xyz="0 0 0" rpy="0 0 0"/>
            <material name="gray">
                <color rgba="0.6 0.6 0.6 1.0"/>
            </material>  
        </visual>
    </link>

    <!-- right_arm -->
    <joint name="joint_1_right" type="revolute">
        <parent link="head"/>
        <child link="motor_1_right"/>
        <origin xyz="0.1 0 0 " rpy="-1.57 0 -1.57"/> <!-- 0.1 매크로로 변경-->
        <axis xyz="0 0 1"/>
        <limit effort="1.0" lower="-3.14" upper="3.14" velocity="1.0"/>
    </joint>

    <link name="motor_1_right">
        <visual>
            <geometry>
                <box size="0.054 0.054 0.126"/>
            </geometry>
            <origin xyz="0 0 -0.063" rpy="0 0 0"/>
            <material name="gray">
                <color rgba="0.6 0.6 0.6 1.0"/>
            </material>  
        </visual>
    </link>

    <joint name="joint_2_right" type="revolute">
        <parent link="motor_1_right"/>
        <child link="motor_2_right"/>
        <origin xyz="0 0 0.23" rpy="1.57 0 0"/> <!-- 0.2 매크로로 변경-->
        <axis xyz="0 0 1"/>
        <limit effort="1.0" lower="-3.14" upper="3.14" velocity="1.0"/>
    </joint>

    <link name="motor_2_right">
        <visual>
            <geometry>
                <box size="0.054 0.054 0.126"/>
            </geometry>
            <origin xyz="0 0 0" rpy="0 0 0"/>
            <material name="gray">
                <color rgba="0.6 0.6 0.6 1.0"/>
            </material>  
        </visual>
    </link>

    <joint name="joint_3_right" type="revolute">
        <parent link="motor_2_right"/>
        <child link="motor_3_right"/>
        <origin xyz="0.3 0 0 " rpy="0 0 0"/> <!-- 0.3 매크로로 변경-->
        <axis xyz="0 0 1"/>
        <limit effort="1.0" lower="-3.14" upper="3.14" velocity="1.0"/>
    </joint>

    <link name="motor_3_right">
        <visual>
            <geometry>
                <box size="0.054 0.054 0.126"/>
            </geometry>
            <origin xyz="0 0 0" rpy="0 0 0"/>
            <material name="gray">
                <color rgba="0.6 0.6 0.6 1.0"/>
            </material>  
        </visual>
    </link>

    <joint name="ee_right_connect" type="fixed">
        <parent link="motor_3_right"/>
        <child link="ee_right"/>
        <origin xyz="0.5 0 0 " rpy="0 0 0"/> <!-- 0.3 매크로로 변경-->
    </joint>

    <link name="ee_right">
        <visual>
            <geometry>
                <sphere radius="0.04"/>
            </geometry>
            <origin xyz="0 0 0" rpy="0 0 0"/>
            <material name="gray">
                <color rgba="0.6 0.6 0.6 1.0"/>
            </material>  
        </visual>
    </link>

</robot>